Workbook

Sheet Description
A2: no cover | M2: with cover

Sheet Input_values
A2: max DC | B2: 1e-06 | C2: T
A3: max AC | B3: 1e-09 | C3: T

Sheet DC-no_cover
C2: 1x mumetal | F2: 2x mumetal
A3: dist_midpoint_to_border (m) | B3: d_mumetal (m) | C3: B (T) | D3: reached Target | F3: B (T) | G3: reached Target
A4: 1 | B4: 0.0015 | C4: 1.695e-06 | D4: =IF(C4<Input_values!$B$2,1,0) -> 0 | F4: 1.4329e-07 | G4: =IF(F4<Input_values!$B$2,1,0) -> 1
A5: 1 | B5: 0.002 | C5: 1.3326e-06 | D5: =IF(C5<Input_values!$B$2,1,0) -> 0 | F5: 1.1532e-07 | G5: =IF(F5<Input_values!$B$2,1,0) -> 1
A6: 1.25 | B6: 0.0015 | C6: 1.4054e-06 | D6: =IF(C6<Input_values!$B$2,1,0) -> 0 | F6: 6.9734e-08 | G6: =IF(F6<Input_values!$B$2,1,0) -> 1
A7: 1.25 | B7: 0.002 | C7: 1.0659e-06 | D7: =IF(C7<Input_values!$B$2,1,0) -> 0 | F7: 4.8504e-08 | G7: =IF(F7<Input_values!$B$2,1,0) -> 1
A8: 1.5 | B8: 0.0015 | C8: 1.313e-06 | D8: =IF(C8<Input_values!$B$2,1,0) -> 0 | F8: 4.9451e-08 | G8: =IF(F8<Input_values!$B$2,1,0) -> 1
A9: 1.5 | B9: 0.002 | C9: 9.8863e-07 | D9: =IF(C9<Input_values!$B$2,1,0) -> 1 | F9: 3.2185e-08 | G9: =IF(F9<Input_values!$B$2,1,0) -> 1
A10: 1.75 | B10: 0.0015 | C10: 1.2658e-06 | D10: =IF(C10<Input_values!$B$2,1,0) -> 0 | F10: 3.9665e-08 | G10: =IF(F10<Input_values!$B$2,1,0) -> 1
A11: 1.75 | B11: 0.002 | C11: 9.5167e-07 | D11: =IF(C11<Input_values!$B$2,1,0) -> 1 | F11: 2.4808e-08 | G11: =IF(F11<Input_values!$B$2,1,0) -> 1
A12: 2 | B12: 0.0015 | C12: 1.2369e-06 | D12: =IF(C12<Input_values!$B$2,1,0) -> 0 | F12: 3.4194e-08 | G12: =IF(F12<Input_values!$B$2,1,0) -> 1
A13: 2 | B13: 0.002 | C13: 9.2968e-07 | D13: =IF(C13<Input_values!$B$2,1,0) -> 1 | F13: 2.0789e-08 | G13: =IF(F13<Input_values!$B$2,1,0) -> 1

Sheet DC-with_cover
C2: 1x mumetal | F2: 2x mumetal
A3: dist_midpoint_to_border (m) | B3: d_mumetal (m) | C3: B (T) | D3: reached target | F3: B (T) | G3: reached target
A4: 1 | B4: 0.002 | C4: 1.2005e-06 | D4: =IF(C4<Input_values!$B$2,1,0) -> 0 | F4: 2.3681e-07 | G4: =IF(F4<Input_values!$B$2,1,0) -> 1
A5: 1 | B5: 0.0015 | C5: 1.5261e-06 | D5: =IF(C5<Input_values!$B$2,1,0) -> 0 | F5: 2.6911e-07 | G5: =IF(F5<Input_values!$B$2,1,0) -> 1
A6: 1.25 | B6: 0.0015 | C6: 1.2946e-06 | D6: =IF(C6<Input_values!$B$2,1,0) -> 0 | F6: 1.0503e-07 | G6: =IF(F6<Input_values!$B$2,1,0) -> 1
A7: 1.25 | B7: 0.002 | C7: 9.8144e-07 | D7: =IF(C7<Input_values!$B$2,1,0) -> 1 | F7: 7.8318e-08 | G7: =IF(F7<Input_values!$B$2,1,0) -> 1
A8: 1.5 | B8: 0.0015 | C8: 1.2308e-06 | D8: =IF(C8<Input_values!$B$2,1,0) -> 0 | F8: 6.8842e-08 | G8: =IF(F8<Input_values!$B$2,1,0) -> 1
A9: 1.5 | B9: 0.002 | C9: 9.2643e-07 | D9: =IF(C9<Input_values!$B$2,1,0) -> 1 | F9: 4.5825e-08 | G9: =IF(F9<Input_values!$B$2,1,0) -> 1
A10: 1.75 | B10: 0.0015 | C10: 1.2017e-06 | D10: =IF(C10<Input_values!$B$2,1,0) -> 0 | F10: 5.5433e-08 | G10: =IF(F10<Input_values!$B$2,1,0) -> 1
A11: 1.75 | B11: 0.002 | C11: 9.0332e-07 | D11: =IF(C11<Input_values!$B$2,1,0) -> 1 | F11: 3.4884e-08 | G11: =IF(F11<Input_values!$B$2,1,0) -> 1
A12: 2 | B12: 0.0015 | C12: 1.1846e-06 | D12: =IF(C12<Input_values!$B$2,1,0) -> 0 | F12: 4.8527e-08 | G12: =IF(F12<Input_values!$B$2,1,0) -> 1
A13: 2 | B13: 0.002 | C13: 8.9026e-07 | D13: =IF(C13<Input_values!$B$2,1,0) -> 1 | F13: 2.9621e-08 | G13: =IF(F13<Input_values!$B$2,1,0) -> 1

Sheet AC-no_cover
E1: 1x mumetal 1x alu | K1: 1x mumetal 2x alu
E2: x direction | G2: y direction | I2: x and y | K2: x direction | M2: y direction | O2: x and y
A3: d_mumetal (m) | B3: d_alu (m) | C3: dist_midpoint_to_border (m) | D3: freq (Hz) | E3: B (T) | F3: reached target | G3: B (T) | H3: rached target | I3: reached target | K3: B (T) | L3: reached target | M3: B (T) | N3: rached target | O3: both
A4: 0.0015 | B4: 0.002 | C4: 2 | D4: 50 | E4: 1.7853e-09 | F4: =IF(E4<Input_values!$B$3,1,0) -> 0 | G4: 1.2395e-09 | H4: =IF(G4<Input_values!$B$3,1,0) -> 0 | I4: =IF(AND(H4=1, F4=1),1,0) -> 0 | K4: 3.4799e-11 | L4: =IF(K4<Input_values!$B$3,1,0) -> 1 | M4: 8.9592e-10 | N4: =IF(M4<Input_values!$B$3,1,0) -> 1 | O4: =IF(AND(N4=1, L4=1),1,0) -> 1
A5: 0.0015 | B5: 0.003 | C5: 2 | D5: 50 | E5: 1.2048e-09 | F5: =IF(E5<Input_values!$B$3,1,0) -> 0 | G5: 9.7167e-10 | H5: =IF(G5<Input_values!$B$3,1,0) -> 1 | I5: =IF(AND(H5=1, F5=1),1,0) -> 0 | K5: 1.5798e-11 | L5: =IF(K5<Input_values!$B$3,1,0) -> 1 | M5: 7.4667e-10 | N5: =IF(M5<Input_values!$B$3,1,0) -> 1 | O5: =IF(AND(N5=1, L5=1),1,0) -> 1
A6: 0.0015 | B6: 0.004 | C6: 2 | D6: 16.7 | E6: 1.4597e-08 | F6: =IF(E6<Input_values!$B$3,1,0) -> 0 | G6: 1.9271e-09 | H6: =IF(G6<Input_values!$B$3,1,0) -> 0 | I6: =IF(AND(H6=1, F6=1),1,0) -> 0 | K6: 3.7313e-10 | L6: =IF(K6<Input_values!$B$3,1,0) -> 1 | M6: 8.8448e-10 | N6: =IF(M6<Input_values!$B$3,1,0) -> 1 | O6: =IF(AND(N6=1, L6=1),1,0) -> 1
A7: 0.0015 | B7: 0.004 | C7: 2 | D7: 50 | E7: 9.0668e-10 | F7: =IF(E7<Input_values!$B$3,1,0) -> 1 | G7: 8.4638e-10 | H7: =IF(G7<Input_values!$B$3,1,0) -> 1 | I7: =IF(AND(H7=1, F7=1),1,0) -> 1 | K7: 9.0232e-12 | L7: =IF(K7<Input_values!$B$3,1,0) -> 1 | M7: 6.9756e-10 | N7: =IF(M7<Input_values!$B$3,1,0) -> 1 | O7: =IF(AND(N7=1, L7=1),1,0) -> 1
A8: 0.0015 | B8: 0.005 | C8: 2 | D8: 16.7 | E8: 1.1878e-08 | F8: =IF(E8<Input_values!$B$3,1,0) -> 0 | G8: 1.49e-09 | H8: =IF(G8<Input_values!$B$3,1,0) -> 0 | I8: =IF(AND(H8=1, F8=1),1,0) -> 0 | K8: 2.4254e-10 | L8: =IF(K8<Input_values!$B$3,1,0) -> 1 | M8: 8.0867e-10 | N8: =IF(M8<Input_values!$B$3,1,0) -> 1 | O8: =IF(AND(N8=1, L8=1),1,0) -> 1
A9: 0.0015 | B9: 0.005 | C9: 2 | D9: 50 | E9: 7.2591e-10 | F9: =IF(E9<Input_values!$B$3,1,0) -> 1 | G9: 7.754e-10 | H9: =IF(G9<Input_values!$B$3,1,0) -> 1 | I9: =IF(AND(H9=1, F9=1),1,0) -> 1 | K9: 5.8599e-12 | L9: =IF(K9<Input_values!$B$3,1,0) -> 1 | M9: 6.768e-10 | N9: =IF(M9<Input_values!$B$3,1,0) -> 1 | O9: =IF(AND(N9=1, L9=1),1,0) -> 1
A10: 0.002 | B10: 0.002 | C10: 2 | D10: 50 | E10: 3.317e-10 | F10: =IF(E10<Input_values!$B$3,1,0) -> 1 | G10: 1.0949e-09 | H10: =IF(G10<Input_values!$B$3,1,0) -> 0 | I10: =IF(AND(H10=1, F10=1),1,0) -> 0 | K10: 6.6844e-12 | L10: =IF(K10<Input_values!$B$3,1,0) -> 1 | M10: 8.6423e-10 | N10: =IF(M10<Input_values!$B$3,1,0) -> 1 | O10: =IF(AND(N10=1, L10=1),1,0) -> 1
A11: 0.002 | B11: 0.003 | C11: 2 | D11: 50 | E11: 2.2388e-10 | F11: =IF(E11<Input_values!$B$3,1,0) -> 1 | G11: 8.3939e-10 | H11: =IF(G11<Input_values!$B$3,1,0) -> 1 | I11: =IF(AND(H11=1, F11=1),1,0) -> 1 | K11: 3.2019e-12 | L11: =IF(K11<Input_values!$B$3,1,0) -> 1 | M11: 7.3357e-10 | N11: =IF(M11<Input_values!$B$3,1,0) -> 1 | O11: =IF(AND(N11=1, L11=1),1,0) -> 1
A12: 0.002 | B12: 0.004 | C12: 2 | D12: 50 | E12: 1.6847e-10 | F12: =IF(E12<Input_values!$B$3,1,0) -> 1 | G12: 7.3067e-10 | H12: =IF(G12<Input_values!$B$3,1,0) -> 1 | I12: =IF(AND(H12=1, F12=1),1,0) -> 1 | K12: 1.9721e-12 | L12: =IF(K12<Input_values!$B$3,1,0) -> 1 | M12: 6.9067e-10 | N12: =IF(M12<Input_values!$B$3,1,0) -> 1 | O12: =IF(AND(N12=1, L12=1),1,0) -> 1
A13: 0.002 | B13: 0.005 | C13: 2 | D13: 16.7 | E13: 4.4813e-09 | F13: =IF(E13<Input_values!$B$3,1,0) -> 0 | G13: 7.0637e-10 | H13: =IF(G13<Input_values!$B$3,1,0) -> 1 | I13: =IF(AND(H13=1, F13=1),1,0) -> 0 | K13: 9.1567e-11 | L13: =IF(K13<Input_values!$B$3,1,0) -> 1 | M13: 8.9412e-10 | N13: =IF(M13<Input_values!$B$3,1,0) -> 1 | O13: =IF(AND(N13=1, L13=1),1,0) -> 1
A14: 0.002 | B14: 0.005 | C14: 2 | D14: 50 | E14: 1.3519e-10 | F14: =IF(E14<Input_values!$B$3,1,0) -> 1 | G14: 6.7389e-10 | H14: =IF(G14<Input_values!$B$3,1,0) -> 1 | I14: =IF(AND(H14=1, F14=1),1,0) -> 1 | K14: 1.429e-12 | L14: =IF(K14<Input_values!$B$3,1,0) -> 1 | M14: 6.7261e-10 | N14: =IF(M14<Input_values!$B$3,1,0) -> 1 | O14: =IF(AND(N14=1, L14=1),1,0) -> 1
A15: 0.0015 | B15: 0.002 | C15: 2 | D15: 16.7 | E15: 2.5611e-08 | F15: =IF(E15<Input_values!$B$3,1,0) -> 0 | G15: 3.8614e-09 | H15: =IF(G15<Input_values!$B$3,1,0) -> 0 | I15: =IF(AND(H15=1, F15=1),1,0) -> 0 | K15: 1.3397e-09 | L15: =IF(K15<Input_values!$B$3,1,0) -> 0 | M15: 1.3223e-09 | N15: =IF(M15<Input_values!$B$3,1,0) -> 0 | O15: =IF(AND(N15=1, L15=1),1,0) -> 0
... A83: 0.002 | B83: 0.005 | C83: 1 | D83: 50 | E83: 2.5782e-09 | F83: =IF(E83<Input_values!$B$3,1,0) -> 0 | G83: 3.0063e-08 | H83: =IF(G83<Input_values!$B$3,1,0) -> 0 | I83: =IF(AND(H83=1, F83=1),1,0) -> 0 | K83: 7.0891e-10 | L83: =IF(K83<Input_values!$B$3,1,0) -> 1 | M83: 3.3752e-08 | N83: =IF(M83<Input_values!$B$3,1,0) -> 0 | O83: =IF(AND(N83=1, L83=1),1,0) -> 0

Sheet AC-with_cover
E1: 1x mumetal 1x alu | K1: 1x mumetal 2x alu | Q1: 2x mumetal 2x alu
E2: x direction | G2: y direction | I2: x and y | K2: x direction | M2: y direction | O2: x and y | Q2: x direction | S2: y direction | U2: x and y
A3: d_mumetal (m) | B3: d_alu (m) | C3: dist_midpoint_to_border (m) | D3: freq (Hz) | E3: B (T) | F3: reached target | G3: B (T) | H3: rached target | I3: reached target | K3: B (T) | L3: reached target | M3: B (T) | N3: rached target | O3: both | Q3: B (T) | R3: reached target | S3: B (T) | T3: rached target | U3: both
A4: 0.0015 | B4: 0.003 | C4: 2 | D4: 50 | E4: 8.8413e-10 | F4: =IF(E4<Input_values!$B$3,1,0) -> 1 | G4: 7.6952e-10 | H4: =IF(G4<Input_values!$B$3,1,0) -> 1 | I4: =IF(AND(H4=1, F4=1),1,0) -> 1 | K4: 1.6279e-11 | L4: =IF(K4<Input_values!$B$3,1,0) -> 1 | M4: 5.8356e-10 | N4: =IF(M4<Input_values!$B$3,1,0) -> 1 | O4: =IF(AND(N4=1, L4=1),1,0) -> 1 | Q4: 5.5122e-13 | R4: =IF(Q4<Input_values!$B$3,1,0) -> 1 | S4: 3.1496e-10 | T4: =IF(S4<Input_values!$B$3,1,0) -> 1 | U4: =IF(AND(T4=1, R4=1),1,0) -> 1
A5: 0.0015 | B5: 0.004 | C5: 2 | D5: 50 | E5: 6.6586e-10 | F5: =IF(E5<Input_values!$B$3,1,0) -> 1 | G5: 6.7474e-10 | H5: =IF(G5<Input_values!$B$3,1,0) -> 1 | I5: =IF(AND(H5=1, F5=1),1,0) -> 1 | K5: 9.2118e-12 | L5: =IF(K5<Input_values!$B$3,1,0) -> 1 | M5: 5.5148e-10 | N5: =IF(M5<Input_values!$B$3,1,0) -> 1 | O5: =IF(AND(N5=1, L5=1),1,0) -> 1 | Q5: 5.9246e-13 | R5: =IF(Q5<Input_values!$B$3,1,0) -> 1 | S5: 3.0191e-10 | T5: =IF(S5<Input_values!$B$3,1,0) -> 1 | U5: =IF(AND(T5=1, R5=1),1,0) -> 1
A6: 0.0015 | B6: 0.005 | C6: 2 | D6: 50 | E6: 5.3329e-10 | F6: =IF(E6<Input_values!$B$3,1,0) -> 1 | G6: 6.208e-10 | H6: =IF(G6<Input_values!$B$3,1,0) -> 1 | I6: =IF(AND(H6=1, F6=1),1,0) -> 1 | K6: 5.9538e-12 | L6: =IF(K6<Input_values!$B$3,1,0) -> 1 | M6: 5.3852e-10 | N6: =IF(M6<Input_values!$B$3,1,0) -> 1 | O6: =IF(AND(N6=1, L6=1),1,0) -> 1 | Q6: 6.3196e-13 | R6: =IF(Q6<Input_values!$B$3,1,0) -> 1 | S6: 2.9655e-10 | T6: =IF(S6<Input_values!$B$3,1,0) -> 1 | U6: =IF(AND(T6=1, R6=1),1,0) -> 1
A7: 0.002 | B7: 0.002 | C7: 2 | D7: 50 | E7: 2.4353e-10 | F7: =IF(E7<Input_values!$B$3,1,0) -> 1 | G7: 8.1044e-10 | H7: =IF(G7<Input_values!$B$3,1,0) -> 1 | I7: =IF(AND(H7=1, F7=1),1,0) -> 1 | K7: 6.8219e-12 | L7: =IF(K7<Input_values!$B$3,1,0) -> 1 | M7: 6.5706e-10 | N7: =IF(M7<Input_values!$B$3,1,0) -> 1 | O7: =IF(AND(N7=1, L7=1),1,0) -> 1 | Q7: 5.8548e-13 | R7: =IF(Q7<Input_values!$B$3,1,0) -> 1 | S7: 3.5386e-10 | T7: =IF(S7<Input_values!$B$3,1,0) -> 1 | U7: =IF(AND(T7=1, R7=1),1,0) -> 1
A8: 0.002 | B8: 0.003 | C8: 2 | D8: 50 | E8: 1.6467e-10 | F8: =IF(E8<Input_values!$B$3,1,0) -> 1 | G8: 6.3451e-10 | H8: =IF(G8<Input_values!$B$3,1,0) -> 1 | I8: =IF(AND(H8=1, F8=1),1,0) -> 1 | K8: 3.0851e-12 | L8: =IF(K8<Input_values!$B$3,1,0) -> 1 | M8: 5.7245e-10 | N8: =IF(M8<Input_values!$B$3,1,0) -> 1 | O8: =IF(AND(N8=1, L8=1),1,0) -> 1 | Q8: 5.8106e-13 | R8: =IF(Q8<Input_values!$B$3,1,0) -> 1 | S8: 3.1463e-10 | T8: =IF(S8<Input_values!$B$3,1,0) -> 1 | U8: =IF(AND(T8=1, R8=1),1,0) -> 1
A9: 0.002 | B9: 0.004 | C9: 2 | D9: 50 | E9: 1.2427e-10 | F9: =IF(E9<Input_values!$B$3,1,0) -> 1 | G9: 5.6144e-10 | H9: =IF(G9<Input_values!$B$3,1,0) -> 1 | I9: =IF(AND(H9=1, F9=1),1,0) -> 1 | K9: 1.8016e-12 | L9: =IF(K9<Input_values!$B$3,1,0) -> 1 | M9: 5.458e-10 | N9: =IF(M9<Input_values!$B$3,1,0) -> 1 | O9: =IF(AND(N9=1, L9=1),1,0) -> 1 | Q9: 6.0396e-13 | R9: =IF(Q9<Input_values!$B$3,1,0) -> 1 | S9: 3.0171e-10 | T9: =IF(S9<Input_values!$B$3,1,0) -> 1 | U9: =IF(AND(T9=1, R9=1),1,0) -> 1
A10: 0.002 | B10: 0.005 | C10: 2 | D10: 50 | E10: 9.9491e-11 | F10: =IF(E10<Input_values!$B$3,1,0) -> 1 | G10: 5.2392e-10 | H10: =IF(G10<Input_values!$B$3,1,0) -> 1 | I10: =IF(AND(H10=1, F10=1),1,0) -> 1 | K10: 1.2012e-12 | L10: =IF(K10<Input_values!$B$3,1,0) -> 1 | M10: 5.3515e-10 | N10: =IF(M10<Input_values!$B$3,1,0) -> 1 | O10: =IF(AND(N10=1, L10=1),1,0) -> 1 | Q10: 6.3573e-13 | R10: =IF(Q10<Input_values!$B$3,1,0) -> 1 | S10: 2.9643e-10 | T10: =IF(S10<Input_values!$B$3,1,0) -> 1 | U10: =IF(AND(T10=1, R10=1),1,0) -> 1
A11: 0.0015 | B11: 0.002 | C11: 2 | D11: 50 | E11: 1.3087e-09 | F11: =IF(E11<Input_values!$B$3,1,0) -> 0 | G11: 9.7103e-10 | H11: =IF(G11<Input_values!$B$3,1,0) -> 1 | I11: =IF(AND(H11=1, F11=1),1,0) -> 0 | K11: 3.6467e-11 | L11: =IF(K11<Input_values!$B$3,1,0) -> 1 | M11: 6.8507e-10 | N11: =IF(M11<Input_values!$B$3,1,0) -> 1 | O11: =IF(AND(N11=1, L11=1),1,0) -> 1 | Q11: 5.8293e-13 | R11: =IF(Q11<Input_values!$B$3,1,0) -> 1 | S11: 3.5442e-10 | T11: =IF(S11<Input_values!$B$3,1,0) -> 1 | U11: =IF(AND(T11=1, R11=1),1,0) -> 1
A12: 0.0015 | B12: 0.003 | C12: 2 | D12: 16.7 | E12: 1.3118e-08 | F12: =IF(E12<Input_values!$B$3,1,0) -> 0 | G12: 3.6565e-09 | H12: =IF(G12<Input_values!$B$3,1,0) -> 0 | I12: =IF(AND(H12=1, F12=1),1,0) -> 0 | K12: 6.8568e-10 | L12: =IF(K12<Input_values!$B$3,1,0) -> 1 | M12: 8.3115e-10 | N12: =IF(M12<Input_values!$B$3,1,0) -> 1 | O12: =IF(AND(N12=1, L12=1),1,0) -> 1 | Q12: 1.6586e-11 | R12: =IF(Q12<Input_values!$B$3,1,0) -> 1 | S12: 4.6635e-10 | T12: =IF(S12<Input_values!$B$3,1,0) -> 1 | U12: =IF(AND(T12=1, R12=1),1,0) -> 1
A13: 0.0015 | B13: 0.004 | C13: 2 | D13: 16.7 | E13: 1.0225e-08 | F13: =IF(E13<Input_values!$B$3,1,0) -> 0 | G13: 2.7521e-09 | H13: =IF(G13<Input_values!$B$3,1,0) -> 0 | I13: =IF(AND(H13=1, F13=1),1,0) -> 0 | K13: 3.9618e-10 | L13: =IF(K13<Input_values!$B$3,1,0) -> 1 | M13: 7.0483e-10 | N13: =IF(M13<Input_values!$B$3,1,0) -> 1 | O13: =IF(AND(N13=1, L13=1),1,0) -> 1 | Q13: 8.3749e-12 | R13: =IF(Q13<Input_values!$B$3,1,0) -> 1 | S13: 3.739e-10 | T13: =IF(S13<Input_values!$B$3,1,0) -> 1 | U13: =IF(AND(T13=1, R13=1),1,0) -> 1
A14: 0.0015 | B14: 0.005 | C14: 2 | D14: 16.7 | E14: 8.3293e-09 | F14: =IF(E14<Input_values!$B$3,1,0) -> 0 | G14: 2.1903e-09 | H14: =IF(G14<Input_values!$B$3,1,0) -> 0 | I14: =IF(AND(H14=1, F14=1),1,0) -> 0 | K14: 2.5614e-10 | L14: =IF(K14<Input_values!$B$3,1,0) -> 1 | M14: 6.4194e-10 | N14: =IF(M14<Input_values!$B$3,1,0) -> 1 | O14: =IF(AND(N14=1, L14=1),1,0) -> 1 | Q14: 5.2893e-12 | R14: =IF(Q14<Input_values!$B$3,1,0) -> 1 | S14: 3.3273e-10 | T14: =IF(S14<Input_values!$B$3,1,0) -> 1 | U14: =IF(AND(T14=1, R14=1),1,0) -> 1
A15: 0.002 | B15: 0.004 | C15: 2 | D15: 16.7 | E15: 3.8589e-09 | F15: =IF(E15<Input_values!$B$3,1,0) -> 0 | G15: 9.1657e-10 | H15: =IF(G15<Input_values!$B$3,1,0) -> 1 | I15: =IF(AND(H15=1, F15=1),1,0) -> 0 | K15: 1.4922e-10 | L15: =IF(K15<Input_values!$B$3,1,0) -> 1 | M15: 8.0965e-10 | N15: =IF(M15<Input_values!$B$3,1,0) -> 1 | O15: =IF(AND(N15=1, L15=1),1,0) -> 1 | Q15: 2.6421e-12 | R15: =IF(Q15<Input_values!$B$3,1,0) -> 1 | S15: 3.786e-10 | T15: =IF(S15<Input_values!$B$3,1,0) -> 1 | U15: =IF(AND(T15=1, R15=1),1,0) -> 1
... A83: 0.002 | B83: 0.003 | C83: 1.75 | D83: 16.7 | E83: 4.6757e-09 | F83: =IF(E83<Input_values!$B$3,1,0) -> 0 | G83: 1.6998e-09 | H83: =IF(G83<Input_values!$B$3,1,0) -> 0 | I83: =IF(AND(H83=1, F83=1),1,0) -> 0 | K83: 2.6227e-10 | L83: =IF(K83<Input_values!$B$3,1,0) -> 1 | M83: 2.2459e-09 | N83: =IF(M83<Input_values!$B$3,1,0) -> 0 | O83: =IF(AND(N83=1, L83=1),1,0) -> 0 | Q83: 7.5612e-11 | R83: =IF(Q83<Input_values!$B$3,1,0) -> 1 | S83: 1.1184e-09 | T83: =IF(S83<Input_values!$B$3,1,0) -> 0 | U83: =IF(AND(T83=1, R83=1),1,0) -> 0

Sheet Magnetic_Map@SA
A2: Magnetic flux density @ senstive area
A3: 1.5m + 0.75m cover with 2x mumetal and 2x aluminium
A6: X-Direction | C6: 1.5mm Mumetal 2mm Aluminium | L6: Y-Direction | N6: 1.5mm Mumetal 2mm Aluminium
A33: X-Direction | C33: 1.5mm Mumetal 5mm Aluminium | L33: Y-Direction | N33: 1.5mm Mumetal 5mm Aluminium

Sheet 2_area_of_interest
E1: 2x mumetal 2x alu | K1: 2x mumetal 2x alu 2 Area of interest
E2: 1 Area of interest | K2: 2 Area of interest
E3: x direction | G3: y direction | I3: x and y | K3: x direction | M3: y direction | O3: x and y | Q3: 1 Area of interest | V3: 2 Area of interest
A4: d_mumetal (m) | B4: d_alu (m) | C4: dist_midpoint_to_border (m) | D4: freq (Hz) | E4: B (T) | F4: reached target | G4: B (T) | H4: rached target | I4: both | K4: B (T) | L4: reached target | M4: B (T) | N4: rached target | O4: both
A5: 0.0015 | B5: 0.002 | C5: 1 | D5: 16.7 | E5: 1.8056e-08 | F5: =IF(E5<Input_values!$B$3,1,0) -> 0 | G5: 1.4748e-08 | H5: =IF(G5<Input_values!$B$3,1,0) -> 0 | I5: =IF(AND(H5=1, F5=1),1,0) -> 0 | K5: 9.4532e-08 | L5: =IF(K5<Input_values!$B$3,1,0) -> 0 | M5: 4.5892e-08 | N5: =IF(M5<Input_values!$B$3,1,0) -> 0 | O5: =IF(AND(N5=1, L5=1),1,0) -> 0
A6: 0.0015 | B6: 0.002 | C6: 1 | D6: 50 | E6: 2.0381e-09 | F6: =IF(E6<Input_values!$B$3,1,0) -> 0 | G6: 1.5338e-08 | H6: =IF(G6<Input_values!$B$3,1,0) -> 0 | I6: =IF(AND(H6=1, F6=1),1,0) -> 0 | K6: 2.4019e-08 | L6: =IF(K6<Input_values!$B$3,1,0) -> 0 | M6: 5.1102e-08 | N6: =IF(M6<Input_values!$B$3,1,0) -> 0 | O6: =IF(AND(N6=1, L6=1),1,0) -> 0
A7: 0.0015 | B7: 0.002 | C7: 1.25 | D7: 16.7 | E7: 4.6044e-09 | F7: =IF(E7<Input_values!$B$3,1,0) -> 0 | G7: 5.6545e-09 | H7: =IF(G7<Input_values!$B$3,1,0) -> 0 | I7: =IF(AND(H7=1, F7=1),1,0) -> 0 | K7: 2.4767e-08 | L7: =IF(K7<Input_values!$B$3,1,0) -> 0 | M7: 1.7951e-08 | N7: =IF(M7<Input_values!$B$3,1,0) -> 0 | O7: =IF(AND(N7=1, L7=1),1,0) -> 0
A8: 0.0015 | B8: 0.002 | C8: 1.25 | D8: 50 | E8: 2.4151e-10 | F8: =IF(E8<Input_values!$B$3,1,0) -> 1 | G8: 5.6631e-09 | H8: =IF(G8<Input_values!$B$3,1,0) -> 0 | I8: =IF(AND(H8=1, F8=1),1,0) -> 0 | K8: 3.1784e-09 | L8: =IF(K8<Input_values!$B$3,1,0) -> 0 | M8: 1.8891e-08 | N8: =IF(M8<Input_values!$B$3,1,0) -> 0 | O8: =IF(AND(N8=1, L8=1),1,0) -> 0
A9: 0.0015 | B9: 0.002 | C9: 1.5 | D9: 16.7 | E9: 1.1551e-09 | F9: =IF(E9<Input_values!$B$3,1,0) -> 0 | G9: 2.161e-09 | H9: =IF(G9<Input_values!$B$3,1,0) -> 0 | I9: =IF(AND(H9=1, F9=1),1,0) -> 0 | K9: 6.3946e-09 | L9: =IF(K9<Input_values!$B$3,1,0) -> 0 | M9: 6.8189e-09 | N9: =IF(M9<Input_values!$B$3,1,0) -> 0 | O9: =IF(AND(N9=1, L9=1),1,0) -> 0
A10: 0.0015 | B10: 0.002 | C10: 1.5 | D10: 50 | E10: 2.8085e-11 | F10: =IF(E10<Input_values!$B$3,1,0) -> 1 | G10: 2.0938e-09 | H10: =IF(G10<Input_values!$B$3,1,0) -> 0 | I10: =IF(AND(H10=1, F10=1),1,0) -> 0 | K10: 3.9551e-10 | L10: =IF(K10<Input_values!$B$3,1,0) -> 1 | M10: 6.8761e-09 | N10: =IF(M10<Input_values!$B$3,1,0) -> 0 | O10: =IF(AND(N10=1, L10=1),1,0) -> 0
A11: 0.0015 | B11: 0.002 | C11: 1.75 | D11: 16.7 | E11: 2.7363e-10 | F11: =IF(E11<Input_values!$B$3,1,0) -> 1 | G11: 8.3583e-10 | H11: =IF(G11<Input_values!$B$3,1,0) -> 1 | I11: =IF(AND(H11=1, F11=1),1,0) -> 1 | K11: 1.5985e-09 | L11: =IF(K11<Input_values!$B$3,1,0) -> 0 | M11: 2.6297e-09 | N11: =IF(M11<Input_values!$B$3,1,0) -> 0 | O11: =IF(AND(N11=1, L11=1),1,0) -> 0
A12: 0.0015 | B12: 0.002 | C12: 1.75 | D12: 50 | E12: 3.15e-12 | F12: =IF(E12<Input_values!$B$3,1,0) -> 1 | G12: 7.8052e-10 | H12: =IF(G12<Input_values!$B$3,1,0) -> 1 | I12: =IF(AND(H12=1, F12=1),1,0) -> 1 | K12: 4.4796e-11 | L12: =IF(K12<Input_values!$B$3,1,0) -> 1 | M12: 2.5662e-09 | N12: =IF(M12<Input_values!$B$3,1,0) -> 0 | O12: =IF(AND(N12=1, L12=1),1,0) -> 0
A13: 0.0015 | B13: 0.002 | C13: 2 | D13: 16.7 | E13: 5.2092e-11 | F13: =IF(E13<Input_values!$B$3,1,0) -> 1 | G13: 3.3045e-10 | H13: =IF(G13<Input_values!$B$3,1,0) -> 1 | I13: =IF(AND(H13=1, F13=1),1,0) -> 1 | K13: 3.8383e-10 | L13: =IF(K13<Input_values!$B$3,1,0) -> 1 | M13: 1.013e-09 | N13: =IF(M13<Input_values!$B$3,1,0) -> 0 | O13: =IF(AND(N13=1, L13=1),1,0) -> 0
A14: 0.0015 | B14: 0.002 | C14: 2 | D14: 50 | E14: 7.653e-13 | F14: =IF(E14<Input_values!$B$3,1,0) -> 1 | G14: 2.9512e-10 | H14: =IF(G14<Input_values!$B$3,1,0) -> 1 | I14: =IF(AND(H14=1, F14=1),1,0) -> 1 | K14: 5.423e-12 | L14: =IF(K14<Input_values!$B$3,1,0) -> 1 | M14: 9.5365e-10 | N14: =IF(M14<Input_values!$B$3,1,0) -> 1 | O14: =IF(AND(N14=1, L14=1),1,0) -> 1
A15: 0.0015 | B15: 0.003 | C15: 1 | D15: 16.7 | E15: 8.9128e-09 | F15: =IF(E15<Input_values!$B$3,1,0) -> 0 | G15: 1.5269e-08 | H15: =IF(G15<Input_values!$B$3,1,0) -> 0 | I15: =IF(AND(H15=1, F15=1),1,0) -> 0 | K15: 6.0487e-08 | L15: =IF(K15<Input_values!$B$3,1,0) -> 0 | M15: 4.3229e-08 | N15: =IF(M15<Input_values!$B$3,1,0) -> 0 | O15: =IF(AND(N15=1, L15=1),1,0) -> 0
A16: 0.0015 | B16: 0.003 | C16: 1 | D16: 50 | E16: 1.3167e-09 | F16: =IF(E16<Input_values!$B$3,1,0) -> 0 | G16: 1.5413e-08 | H16: =IF(G16<Input_values!$B$3,1,0) -> 0 | I16: =IF(AND(H16=1, F16=1),1,0) -> 0 | K16: 1.6541e-08 | L16: =IF(K16<Input_values!$B$3,1,0) -> 0 | M16: 5.0596e-08 | N16: =IF(M16<Input_values!$B$3,1,0) -> 0 | O16: =IF(AND(N16=1, L16=1),1,0) -> 0
... A84: 0.002 | B84: 0.005 | C84: 2 | D84: 50 | E84: 8.8229e-13 | F84: =IF(E84<Input_values!$B$3,1,0) -> 1 | G84: 2.9502e-10 | H84: =IF(G84<Input_values!$B$3,1,0) -> 1 | I84: =IF(AND(H84=1, F84=1),1,0) -> 1 | K84: 4.2975e-12 | L84: =IF(K84<Input_values!$B$3,1,0) -> 1 | M84: 9.5363e-10 | N84: =IF(M84<Input_values!$B$3,1,0) -> 1 | O84: =IF(AND(N84=1, L84=1),1,0) -> 1

Sheet 3xMumetal_2xAlu
E1: 3x mumetal 2x alu 1 Area of interest | K1: 3x mumetal 2x alu 2 Area of interest
E2: 1 Area of interest | K2: 2 Area of interest
E3: x direction | G3: y direction | I3: x and y | K3: x direction | M3: y direction | O3: x and y
A4: d_mumetal (m) | B4: d_alu (m) | C4: dist_hearth_to_feet (m) | D4: freq (Hz) | E4: B (T) | F4: reached target | G4: B (T) | H4: rached target | I4: both | K4: B (T) | L4: reached target | M4: B (T) | N4: rached target | O4: both | R4: 1 Area of interest | X4: 2 Area of interest
A5: 0.0015 | B5: 0.005 | C5: 1 | D5: 16.7 | E5: 2.7428e-09 | F5: =IF(E5<Input_values!$B$3,1,0) -> 0 | G5: 1.2495e-08 | H5: =IF(G5<Input_values!$B$3,1,0) -> 0 | I5: =IF(AND(H5=1, F5=1),1,0) -> 0 | K5: 2.8935e-08 | L5: =IF(K5<Input_values!$B$3,1,0) -> 0 | M5: 3.8924e-08 | N5: =IF(M5<Input_values!$B$3,1,0) -> 0 | O5: =IF(AND(N5=1, L5=1),1,0) -> 0
A6: 0.0015 | B6: 0.005 | C6: 1 | D6: 50 | E6: 1.0182e-09 | F6: =IF(E6<Input_values!$B$3,1,0) -> 0 | G6: 1.2922e-08 | H6: =IF(G6<Input_values!$B$3,1,0) -> 0 | I6: =IF(AND(H6=1, F6=1),1,0) -> 0 | K6: 1.2485e-08 | L6: =IF(K6<Input_values!$B$3,1,0) -> 0 | M6: 4.3099e-08 | N6: =IF(M6<Input_values!$B$3,1,0) -> 0 | O6: =IF(AND(N6=1, L6=1),1,0) -> 0
A7: 0.002 | B7: 0.005 | C7: 1 | D7: 16.7 | E7: 2.7607e-09 | F7: =IF(E7<Input_values!$B$3,1,0) -> 0 | G7: 1.2562e-08 | H7: =IF(G7<Input_values!$B$3,1,0) -> 0 | I7: =IF(AND(H7=1, F7=1),1,0) -> 0 | K7: 2.9102e-08 | L7: =IF(K7<Input_values!$B$3,1,0) -> 0 | M7: 3.9103e-08 | N7: =IF(M7<Input_values!$B$3,1,0) -> 0 | O7: =IF(AND(N7=1, L7=1),1,0) -> 0
A8: 0.002 | B8: 0.005 | C8: 1 | D8: 50 | E8: 1.018e-09 | F8: =IF(E8<Input_values!$B$3,1,0) -> 0 | G8: 1.2926e-08 | H8: =IF(G8<Input_values!$B$3,1,0) -> 0 | I8: =IF(AND(H8=1, F8=1),1,0) -> 0 | K8: 1.2483e-08 | L8: =IF(K8<Input_values!$B$3,1,0) -> 0 | M8: 4.3117e-08 | N8: =IF(M8<Input_values!$B$3,1,0) -> 0 | O8: =IF(AND(N8=1, L8=1),1,0) -> 0
A9: 0.0015 | B9: 0.004 | C9: 1 | D9: 16.7 | E9: 4.4318e-09 | F9: =IF(E9<Input_values!$B$3,1,0) -> 0 | G9: 1.2671e-08 | H9: =IF(G9<Input_values!$B$3,1,0) -> 0 | I9: =IF(AND(H9=1, F9=1),1,0) -> 0 | K9: 3.8614e-08 | L9: =IF(K9<Input_values!$B$3,1,0) -> 0 | M9: 3.806e-08 | N9: =IF(M9<Input_values!$B$3,1,0) -> 0 | O9: =IF(AND(N9=1, L9=1),1,0) -> 0
A10: 0.0015 | B10: 0.004 | C10: 1 | D10: 50 | E10: 1.0895e-09 | F10: =IF(E10<Input_values!$B$3,1,0) -> 0 | G10: 1.2908e-08 | H10: =IF(G10<Input_values!$B$3,1,0) -> 0 | I10: =IF(AND(H10=1, F10=1),1,0) -> 0 | K10: 1.3495e-08 | L10: =IF(K10<Input_values!$B$3,1,0) -> 0 | M10: 4.2872e-08 | N10: =IF(M10<Input_values!$B$3,1,0) -> 0 | O10: =IF(AND(N10=1, L10=1),1,0) -> 0
A11: 0.002 | B11: 0.004 | C11: 1 | D11: 16.7 | E11: 4.4643e-09 | F11: =IF(E11<Input_values!$B$3,1,0) -> 0 | G11: 1.2752e-08 | H11: =IF(G11<Input_values!$B$3,1,0) -> 0 | I11: =IF(AND(H11=1, F11=1),1,0) -> 0 | K11: 3.8854e-08 | L11: =IF(K11<Input_values!$B$3,1,0) -> 0 | M11: 3.8266e-08 | N11: =IF(M11<Input_values!$B$3,1,0) -> 0 | O11: =IF(AND(N11=1, L11=1),1,0) -> 0
A12: 0.002 | B12: 0.004 | C12: 1 | D12: 50 | E12: 1.0893e-09 | F12: =IF(E12<Input_values!$B$3,1,0) -> 0 | G12: 1.2911e-08 | H12: =IF(G12<Input_values!$B$3,1,0) -> 0 | I12: =IF(AND(H12=1, F12=1),1,0) -> 0 | K12: 1.3492e-08 | L12: =IF(K12<Input_values!$B$3,1,0) -> 0 | M12: 4.2887e-08 | N12: =IF(M12<Input_values!$B$3,1,0) -> 0 | O12: =IF(AND(N12=1, L12=1),1,0) -> 0
A13: 0.0015 | B13: 0.003 | C13: 1 | D13: 16.7 | E13: 8.2014e-09 | F13: =IF(E13<Input_values!$B$3,1,0) -> 0 | G13: 1.2883e-08 | H13: =IF(G13<Input_values!$B$3,1,0) -> 0 | I13: =IF(AND(H13=1, F13=1),1,0) -> 0 | K13: 5.5815e-08 | L13: =IF(K13<Input_values!$B$3,1,0) -> 0 | M13: 3.6532e-08 | N13: =IF(M13<Input_values!$B$3,1,0) -> 0 | O13: =IF(AND(N13=1, L13=1),1,0) -> 0
A14: 0.0015 | B14: 0.003 | C14: 1 | D14: 50 | E14: 1.2475e-09 | F14: =IF(E14<Input_values!$B$3,1,0) -> 0 | G14: 1.2945e-08 | H14: =IF(G14<Input_values!$B$3,1,0) -> 0 | I14: =IF(AND(H14=1, F14=1),1,0) -> 0 | K14: 1.5687e-08 | L14: =IF(K14<Input_values!$B$3,1,0) -> 0 | M14: 4.255e-08 | N14: =IF(M14<Input_values!$B$3,1,0) -> 0 | O14: =IF(AND(N14=1, L14=1),1,0) -> 0
A15: 0.002 | B15: 0.003 | C15: 1 | D15: 16.7 | E15: 8.2692e-09 | F15: =IF(E15<Input_values!$B$3,1,0) -> 0 | G15: 1.2989e-08 | H15: =IF(G15<Input_values!$B$3,1,0) -> 0 | I15: =IF(AND(H15=1, F15=1),1,0) -> 0 | K15: 5.6193e-08 | L15: =IF(K15<Input_values!$B$3,1,0) -> 0 | M15: 3.6778e-08 | N15: =IF(M15<Input_values!$B$3,1,0) -> 0 | O15: =IF(AND(N15=1, L15=1),1,0) -> 0
A16: 0.002 | B16: 0.003 | C16: 1 | D16: 50 | E16: 1.2471e-09 | F16: =IF(E16<Input_values!$B$3,1,0) -> 0 | G16: 1.2947e-08 | H16: =IF(G16<Input_values!$B$3,1,0) -> 0 | I16: =IF(AND(H16=1, F16=1),1,0) -> 0 | K16: 1.5682e-08 | L16: =IF(K16<Input_values!$B$3,1,0) -> 0 | M16: 4.2562e-08 | N16: =IF(M16<Input_values!$B$3,1,0) -> 0 | O16: =IF(AND(N16=1, L16=1),1,0) -> 0
... A84: 0.002 | B84: 0.002 | C84: 2 | D84: 50 | E84: 6.6269e-13 | F84: =IF(E84<Input_values!$B$3,1,0) -> 1 | G84: 2.8994e-10 | H84: =IF(G84<Input_values!$B$3,1,0) -> 1 | I84: =IF(AND(H84=1, F84=1),1,0) -> 1 | K84: 5.18e-12 | L84: =IF(K84<Input_values!$B$3,1,0) -> 1 | M84: 8.8445e-10 | N84: =IF(M84<Input_values!$B$3,1,0) -> 1 | O84: =IF(AND(N84=1, L84=1),1,0) -> 1

Sheet air_gap
A1: with air gap | E1: 2x mumetal 2x alu 1 Area of interest | K1: 2x mumetal 2x alu 2 Area of interest | Q1: 1 Area of interest | Z1: 2 Area of interest
E2: 1 Area of interest | K2: 2 Area of interest
E3: x direction | G3: y direction | I3: x and y | K3: x direction | M3: y direction | O3: x and y
A4: d_mumetal (m) | B4: d_alu (m) | C4: dist_midpoint_to_border (m) | D4: freq (Hz) | E4: B (T) | F4: reached target | G4: B (T) | H4: rached target | I4: both | K4: B (T) | L4: reached target | M4: B (T) | N4: rached target | O4: both
A5: 0.0015 | B5: 0.002 | C5: 2 | D5: 16.7 | E5: 1.1839e-08 | F5: =IF(E5<Input_values!$B$3,1,0) -> 0 | G5: 1.0245e-09 | H5: =IF(G5<Input_values!$B$3,1,0) -> 0 | I5: =IF(AND(H5=1, F5=1),1,0) -> 0 | K5: 1.5232e-08 | L5: =IF(K5<Input_values!$B$3,1,0) -> 0 | M5: 1.3875e-09 | N5: =IF(M5<Input_values!$B$3,1,0) -> 0 | O5: =IF(AND(N5=1, L5=1),1,0) -> 0
A6: 0.0015 | B6: 0.002 | C6: 2 | D6: 50 | E6: 1.8126e-08 | F6: =IF(E6<Input_values!$B$3,1,0) -> 0 | G6: 1.8674e-09 | H6: =IF(G6<Input_values!$B$3,1,0) -> 0 | I6: =IF(AND(H6=1, F6=1),1,0) -> 0 | K6: 2.3071e-08 | L6: =IF(K6<Input_values!$B$3,1,0) -> 0 | M6: 2.5898e-09 | N6: =IF(M6<Input_values!$B$3,1,0) -> 0 | O6: =IF(AND(N6=1, L6=1),1,0) -> 0
A7: 0.0015 | B7: 0.003 | C7: 2 | D7: 16.7 | E7: 1.0516e-08 | F7: =IF(E7<Input_values!$B$3,1,0) -> 0 | G7: 1.2975e-09 | H7: =IF(G7<Input_values!$B$3,1,0) -> 0 | I7: =IF(AND(H7=1, F7=1),1,0) -> 0 | K7: 1.3619e-08 | L7: =IF(K7<Input_values!$B$3,1,0) -> 0 | M7: 1.6725e-09 | N7: =IF(M7<Input_values!$B$3,1,0) -> 0 | O7: =IF(AND(N7=1, L7=1),1,0) -> 0
A8: 0.0015 | B8: 0.003 | C8: 2 | D8: 50 | E8: 1.6067e-08 | F8: =IF(E8<Input_values!$B$3,1,0) -> 0 | G8: 2.2819e-09 | H8: =IF(G8<Input_values!$B$3,1,0) -> 0 | I8: =IF(AND(H8=1, F8=1),1,0) -> 0 | K8: 2.0541e-08 | L8: =IF(K8<Input_values!$B$3,1,0) -> 0 | M8: 3.0282e-09 | N8: =IF(M8<Input_values!$B$3,1,0) -> 0 | O8: =IF(AND(N8=1, L8=1),1,0) -> 0
A9: 0.0015 | B9: 0.004 | C9: 2 | D9: 16.7 | E9: 9.7033e-09 | F9: =IF(E9<Input_values!$B$3,1,0) -> 0 | G9: 1.132e-09 | H9: =IF(G9<Input_values!$B$3,1,0) -> 0 | I9: =IF(AND(H9=1, F9=1),1,0) -> 0 | K9: 1.2615e-08 | L9: =IF(K9<Input_values!$B$3,1,0) -> 0 | M9: 1.4995e-09 | N9: =IF(M9<Input_values!$B$3,1,0) -> 0 | O9: =IF(AND(N9=1, L9=1),1,0) -> 0
A10: 0.0015 | B10: 0.004 | C10: 2 | D10: 50 | E10: 1.4819e-08 | F10: =IF(E10<Input_values!$B$3,1,0) -> 0 | G10: 2.0259e-09 | H10: =IF(G10<Input_values!$B$3,1,0) -> 0 | I10: =IF(AND(H10=1, F10=1),1,0) -> 0 | K10: 1.8994e-08 | L10: =IF(K10<Input_values!$B$3,1,0) -> 0 | M10: 2.7578e-09 | N10: =IF(M10<Input_values!$B$3,1,0) -> 0 | O10: =IF(AND(N10=1, L10=1),1,0) -> 0
A11: 0.0015 | B11: 0.005 | C11: 2 | D11: 16.7 | E11: 9.1276e-09 | F11: =IF(E11<Input_values!$B$3,1,0) -> 0 | G11: 1.0245e-09 | H11: =IF(G11<Input_values!$B$3,1,0) -> 0 | I11: =IF(AND(H11=1, F11=1),1,0) -> 0 | K11: 1.1896e-08 | L11: =IF(K11<Input_values!$B$3,1,0) -> 0 | M11: 1.3875e-09 | N11: =IF(M11<Input_values!$B$3,1,0) -> 0 | O11: =IF(AND(N11=1, L11=1),1,0) -> 0
A12: 0.0015 | B12: 0.005 | C12: 2 | D12: 50 | E12: 1.3971e-08 | F12: =IF(E12<Input_values!$B$3,1,0) -> 0 | G12: 1.8674e-09 | H12: =IF(G12<Input_values!$B$3,1,0) -> 0 | I12: =IF(AND(H12=1, F12=1),1,0) -> 0 | K12: 1.7937e-08 | L12: =IF(K12<Input_values!$B$3,1,0) -> 0 | M12: 2.5898e-09 | N12: =IF(M12<Input_values!$B$3,1,0) -> 0 | O12: =IF(AND(N12=1, L12=1),1,0) -> 0
A13: 0.002 | B13: 0.002 | C13: 2 | D13: 16.7 | E13: 1.2982e-08 | F13: =IF(E13<Input_values!$B$3,1,0) -> 0 | G13: 1.1809e-09 | H13: =IF(G13<Input_values!$B$3,1,0) -> 0 | I13: =IF(AND(H13=1, F13=1),1,0) -> 0 | K13: 1.66e-08 | L13: =IF(K13<Input_values!$B$3,1,0) -> 0 | M13: 1.5798e-09 | N13: =IF(M13<Input_values!$B$3,1,0) -> 0 | O13: =IF(AND(N13=1, L13=1),1,0) -> 0
A14: 0.002 | B14: 0.002 | C14: 2 | D14: 50 | E14: 1.8074e-08 | F14: =IF(E14<Input_values!$B$3,1,0) -> 0 | G14: 1.8584e-09 | H14: =IF(G14<Input_values!$B$3,1,0) -> 0 | I14: =IF(AND(H14=1, F14=1),1,0) -> 0 | K14: 2.3012e-08 | L14: =IF(K14<Input_values!$B$3,1,0) -> 0 | M14: 2.5783e-09 | N14: =IF(M14<Input_values!$B$3,1,0) -> 0 | O14: =IF(AND(N14=1, L14=1),1,0) -> 0
A15: 0.002 | B15: 0.003 | C15: 2 | D15: 16.7 | E15: 1.1483e-08 | F15: =IF(E15<Input_values!$B$3,1,0) -> 0 | G15: 1.5164e-09 | H15: =IF(G15<Input_values!$B$3,1,0) -> 0 | I15: =IF(AND(H15=1, F15=1),1,0) -> 0 | K15: 1.4785e-08 | L15: =IF(K15<Input_values!$B$3,1,0) -> 0 | M15: 1.9312e-09 | N15: =IF(M15<Input_values!$B$3,1,0) -> 0 | O15: =IF(AND(N15=1, L15=1),1,0) -> 0
A16: 0.002 | B16: 0.003 | C16: 2 | D16: 50 | E16: 1.6026e-08 | F16: =IF(E16<Input_values!$B$3,1,0) -> 0 | G16: 2.2689e-09 | H16: =IF(G16<Input_values!$B$3,1,0) -> 0 | I16: =IF(AND(H16=1, F16=1),1,0) -> 0 | K16: 2.0495e-08 | L16: =IF(K16<Input_values!$B$3,1,0) -> 0 | M16: 3.012e-09 | N16: =IF(M16<Input_values!$B$3,1,0) -> 0 | O16: =IF(AND(N16=1, L16=1),1,0) -> 0
... A84: 0.002 | B84: 0.005 | C84: 1 | D84: 50 | E84: 2.4715e-08 | F84: =IF(E84<Input_values!$B$3,1,0) -> 0 | G84: 7.5693e-09 | H84: =IF(G84<Input_values!$B$3,1,0) -> 0 | I84: =IF(AND(H84=1, F84=1),1,0) -> 0 | K84: 8.6348e-08 | L84: =IF(K84<Input_values!$B$3,1,0) -> 0 | M84: 1.8778e-08 | N84: =IF(M84<Input_values!$B$3,1,0) -> 0 | O84: =IF(AND(N84=1, L84=1),1,0) -> 0

Sheet graphics
A1: 2 layer mumetal and 2 layer aluminium
AF3: 2x mumetal 2x alu 1 Area of interest | AL3: 2x mumetal 2x alu 2 Area of interest
AF4: x direction | AH4: y direction | AJ4: x and y | AL4: x direction | AN4: y direction | AP4: x and y
U5: x direction / 16.7 Hz | AB5: d_mumetal (m) | AC5: d_alu (m) | AD5: dist_midpoint_to_border (m) | AE5: freq (Hz) | AF5: B (T) | AG5: reached target | AH5: B (T) | AI5: rached target | AJ5: both | AL5: B (T) | AM5: reached target | AN5: B (T) | AO5: rached target | AP5: both
U6: d_alu (mm) | V6: 1 | W6: 1.25 | X6: 1.5 | Y6: 1.75 | Z6: 2 | AB6: 0.0015 | AC6: 0.002 | AD6: 1 | AE6: 16.7 | AF6: 1.8056e-08 | AG6: =IF(AF6<Input_values!$B$3,1,0) -> 0 | AH6: 1.4748e-08 | AI6: =IF(AH6<Input_values!$B$3,1,0) -> 0 | AJ6: =IF(AND(AI6=1, AG6=1),1,0) -> 0 | AL6: 9.4532e-08 | AM6: =IF(AL6<Input_values!$B$3,1,0) -> 0 | AN6: 4.5892e-08 | AO6: =IF(AN6<Input_values!$B$3,1,0) -> 0 | AP6: =IF(AND(AO6=1, AM6=1),1,0) -> 0
U7: 2 | V7: =AF6 -> 1.8056e-08 | W7: =AF14 -> 4.6044e-09 | X7: =AF22 -> 1.1551e-09 | Y7: =AF30 -> 2.7363e-10 | Z7: =AF38 -> 5.2092e-11 | AB7: 0.0015 | AC7: 0.003 | AD7: 1 | AE7: 16.7 | AF7: 8.9128e-09 | AG7: =IF(AF7<Input_values!$B$3,1,0) -> 0 | AH7: 1.5269e-08 | AI7: =IF(AH7<Input_values!$B$3,1,0) -> 0 | AJ7: =IF(AND(AI7=1, AG7=1),1,0) -> 0 | AL7: 6.0487e-08 | AM7: =IF(AL7<Input_values!$B$3,1,0) -> 0 | AN7: 4.3229e-08 | AO7: =IF(AN7<Input_values!$B$3,1,0) -> 0 | AP7: =IF(AND(AO7=1, AM7=1),1,0) -> 0
U8: 3 | V8: =AF7 -> 8.9128e-09 | W8: =AF15 -> 1.7913e-09 | X8: =AF23 -> 3.4703e-10 | Y8: =AF31 -> 5.93e-11 | Z8: =AF39 -> 1.7335e-11 | AB8: 0.0015 | AC8: 0.004 | AD8: 1 | AE8: 16.7 | AF8: 4.7955e-09 | AG8: =IF(AF8<Input_values!$B$3,1,0) -> 0 | AH8: 1.4978e-08 | AI8: =IF(AH8<Input_values!$B$3,1,0) -> 0 | AJ8: =IF(AND(AI8=1, AG8=1),1,0) -> 0 | AL8: 4.1605e-08 | AM8: =IF(AL8<Input_values!$B$3,1,0) -> 0 | AN8: 4.4932e-08 | AO8: =IF(AN8<Input_values!$B$3,1,0) -> 0 | AP8: =IF(AND(AO8=1, AM8=1),1,0) -> 0
U9: 4 | V9: =AF8 -> 4.7955e-09 | W9: =AF16 -> 7.5352e-10 | X9: =AF24 -> 1.0876e-10 | Y9: =AF32 -> 1.296e-11 | Z9: =AF40 -> 8.7617e-12 | AB9: 0.0015 | AC9: 0.005 | AD9: 1 | AE9: 16.7 | AF9: 2.9522e-09 | AG9: =IF(AF9<Input_values!$B$3,1,0) -> 0 | AH9: 1.4748e-08 | AI9: =IF(AH9<Input_values!$B$3,1,0) -> 0 | AJ9: =IF(AND(AI9=1, AG9=1),1,0) -> 0 | AL9: 3.0988e-08 | AM9: =IF(AL9<Input_values!$B$3,1,0) -> 0 | AN9: 4.5892e-08 | AO9: =IF(AN9<Input_values!$B$3,1,0) -> 0 | AP9: =IF(AND(AO9=1, AM9=1),1,0) -> 0
U10: 5 | V10: =AF9 -> 2.9522e-09 | W10: =AF17 -> 3.8229e-10 | X10: =AF25 -> 4.4416e-11 | Y10: =AF33 -> 4.934e-12 | Z10: =AF41 -> 5.4894e-12 | AB10: 0.002 | AC10: 0.002 | AD10: 1 | AE10: 16.7 | AF10: 1.8178e-08 | AG10: =IF(AF10<Input_values!$B$3,1,0) -> 0 | AH10: 1.485e-08 | AI10: =IF(AH10<Input_values!$B$3,1,0) -> 0 | AJ10: =IF(AND(AI10=1, AG10=1),1,0) -> 0 | AL10: 9.4941e-08 | AM10: =IF(AL10<Input_values!$B$3,1,0) -> 0 | AN10: 4.6168e-08 | AO10: =IF(AN10<Input_values!$B$3,1,0) -> 0 | AP10: =IF(AND(AO10=1, AM10=1),1,0) -> 0
AB11: 0.002 | AC11: 0.003 | AD11: 1 | AE11: 16.7 | AF11: 8.9576e-09 | AG11: =IF(AF11<Input_values!$B$3,1,0) -> 0 | AH11: 1.5432e-08 | AI11: =IF(AH11<Input_values!$B$3,1,0) -> 0 | AJ11: =IF(AND(AI11=1, AG11=1),1,0) -> 0 | AL11: 6.0687e-08 | AM11: =IF(AL11<Input_values!$B$3,1,0) -> 0 | AN11: 4.3617e-08 | AO11: =IF(AN11<Input_values!$B$3,1,0) -> 0 | AP11: =IF(AND(AO11=1, AM11=1),1,0) -> 0
U12: y direction / 16.7 Hz | AB12: 0.002 | AC12: 0.004 | AD12: 1 | AE12: 16.7 | AF12: 4.8139e-09 | AG12: =IF(AF12<Input_values!$B$3,1,0) -> 0 | AH12: 1.5101e-08 | AI12: =IF(AH12<Input_values!$B$3,1,0) -> 0 | AJ12: =IF(AND(AI12=1, AG12=1),1,0) -> 0 | AL12: 4.1716e-08 | AM12: =IF(AL12<Input_values!$B$3,1,0) -> 0 | AN12: 4.5253e-08 | AO12: =IF(AN12<Input_values!$B$3,1,0) -> 0 | AP12: =IF(AND(AO12=1, AM12=1),1,0) -> 0
U13: d_alu (m) | V13: 1 | W13: 1.25 | X13: 1.5 | Y13: 1.75 | Z13: 2 | AB13: 0.002 | AC13: 0.005 | AD13: 1 | AE13: 16.7 | AF13: 2.9602e-09 | AG13: =IF(AF13<Input_values!$B$3,1,0) -> 0 | AH13: 1.485e-08 | AI13: =IF(AH13<Input_values!$B$3,1,0) -> 0 | AJ13: =IF(AND(AI13=1, AG13=1),1,0) -> 0 | AL13: 3.1055e-08 | AM13: =IF(AL13<Input_values!$B$3,1,0) -> 0 | AN13: 4.6168e-08 | AO13: =IF(AN13<Input_values!$B$3,1,0) -> 0 | AP13: =IF(AND(AO13=1, AM13=1),1,0) -> 0
U14: 2 | V14: =AH6 -> 1.4748e-08 | W14: =AH14 -> 5.6545e-09 | X14: =AH22 -> 2.161e-09 | Y14: =AH30 -> 8.3583e-10 | Z14: =AH38 -> 3.3045e-10 | AB14: 0.0015 | AC14: 0.002 | AD14: 1.25 | AE14: 16.7 | AF14: 4.6044e-09 | AG14: =IF(AF14<Input_values!$B$3,1,0) -> 0 | AH14: 5.6545e-09 | AI14: =IF(AH14<Input_values!$B$3,1,0) -> 0 | AJ14: =IF(AND(AI14=1, AG14=1),1,0) -> 0 | AL14: 2.4767e-08 | AM14: =IF(AL14<Input_values!$B$3,1,0) -> 0 | AN14: 1.7951e-08 | AO14: =IF(AN14<Input_values!$B$3,1,0) -> 0 | AP14: =IF(AND(AO14=1, AM14=1),1,0) -> 0
U15: 3 | V15: =AH7 -> 1.5269e-08 | W15: =AH15 -> 6.358e-09 | X15: =AH23 -> 2.6253e-09 | Y15: =AH31 -> 1.0928e-09 | Z15: =AH39 -> 4.6423e-10 | AB15: 0.0015 | AC15: 0.003 | AD15: 1.25 | AE15: 16.7 | AF15: 1.7913e-09 | AG15: =IF(AF15<Input_values!$B$3,1,0) -> 0 | AH15: 6.358e-09 | AI15: =IF(AH15<Input_values!$B$3,1,0) -> 0 | AJ15: =IF(AND(AI15=1, AG15=1),1,0) -> 0 | AL15: 1.2762e-08 | AM15: =IF(AL15<Input_values!$B$3,1,0) -> 0 | AN15: 1.8212e-08 | AO15: =IF(AN15<Input_values!$B$3,1,0) -> 0 | AP15: =IF(AND(AO15=1, AM15=1),1,0) -> 0
U16: 4 | V16: =AH8 -> 1.4978e-08 | W16: =AH16 -> 5.9056e-09 | X16: =AH24 -> 2.3135e-09 | Y16: =AH32 -> 9.1656e-10 | Z16: =AH40 -> 3.7169e-10 | AB16: 0.0015 | AC16: 0.004 | AD16: 1.25 | AE16: 16.7 | AF16: 7.5352e-10 | AG16: =IF(AF16<Input_values!$B$3,1,0) -> 1 | AH16: 5.9056e-09 | AI16: =IF(AH16<Input_values!$B$3,1,0) -> 0 | AJ16: =IF(AND(AI16=1, AG16=1),1,0) -> 0 | AL16: 7.1596e-09 | AM16: =IF(AL16<Input_values!$B$3,1,0) -> 0 | AN16: 1.8096e-08 | AO16: =IF(AN16<Input_values!$B$3,1,0) -> 0 | AP16: =IF(AND(AO16=1, AM16=1),1,0) -> 0
U17: 5 | V17: =AH9 -> 1.4748e-08 | W17: =AH17 -> 5.6545e-09 | X17: =AH25 -> 2.161e-09 | Y17: =AH33 -> 8.3583e-10 | Z17: =AH41 -> 3.3045e-10 | AB17: 0.0015 | AC17: 0.005 | AD17: 1.25 | AE17: 16.7 | AF17: 3.8229e-10 | AG17: =IF(AF17<Input_values!$B$3,1,0) -> 1 | AH17: 5.6545e-09 | AI17: =IF(AH17<Input_values!$B$3,1,0) -> 0 | AJ17: =IF(AND(AI17=1, AG17=1),1,0) -> 0 | AL17: 4.5508e-09 | AM17: =IF(AL17<Input_values!$B$3,1,0) -> 0 | AN17: 1.7951e-08 | AO17: =IF(AN17<Input_values!$B$3,1,0) -> 0 | AP17: =IF(AND(AO17=1, AM17=1),1,0) -> 0
AB18: 0.002 | AC18: 0.002 | AD18: 1.25 | AE18: 16.7 | AF18: 4.6532e-09 | AG18: =IF(AF18<Input_values!$B$3,1,0) -> 0 | AH18: 5.6982e-09 | AI18: =IF(AH18<Input_values!$B$3,1,0) -> 0 | AJ18: =IF(AND(AI18=1, AG18=1),1,0) -> 0 | AL18: 2.4923e-08 | AM18: =IF(AL18<Input_values!$B$3,1,0) -> 0 | AN18: 1.8072e-08 | AO18: =IF(AN18<Input_values!$B$3,1,0) -> 0 | AP18: =IF(AND(AO18=1, AM18=1),1,0) -> 0
U19: x direction / 50 Hz | AB19: 0.002 | AC19: 0.003 | AD19: 1.25 | AE19: 16.7 | AF19: 1.8082e-09 | AG19: =IF(AF19<Input_values!$B$3,1,0) -> 0 | AH19: 6.4328e-09 | AI19: =IF(AH19<Input_values!$B$3,1,0) -> 0 | AJ19: =IF(AND(AI19=1, AG19=1),1,0) -> 0 | AL19: 1.2823e-08 | AM19: =IF(AL19<Input_values!$B$3,1,0) -> 0 | AN19: 1.8401e-08 | AO19: =IF(AN19<Input_values!$B$3,1,0) -> 0 | AP19: =IF(AND(AO19=1, AM19=1),1,0) -> 0
U20: d_alu (m) | V20: 1 | W20: 1.25 | X20: 1.5 | Y20: 1.75 | Z20: 2 | AB20: 0.002 | AC20: 0.004 | AD20: 1.25 | AE20: 16.7 | AF20: 7.5983e-10 | AG20: =IF(AF20<Input_values!$B$3,1,0) -> 1 | AH20: 5.96e-09 | AI20: =IF(AH20<Input_values!$B$3,1,0) -> 0 | AJ20: =IF(AND(AI20=1, AG20=1),1,0) -> 0 | AL20: 7.1859e-09 | AM20: =IF(AL20<Input_values!$B$3,1,0) -> 0 | AN20: 1.8241e-08 | AO20: =IF(AN20<Input_values!$B$3,1,0) -> 0 | AP20: =IF(AND(AO20=1, AM20=1),1,0) -> 0
U21: 2 | V21: =AF46 -> 2.0381e-09 | W21: =AF54 -> 2.4151e-10 | X21: =AF62 -> 2.8085e-11 | Y21: =AF70 -> 3.15e-12 | Z21: =AF78 -> 7.653e-13 | AB21: 0.002 | AC21: 0.005 | AD21: 1.25 | AE21: 16.7 | AF21: 3.841e-10 | AG21: =IF(AF21<Input_values!$B$3,1,0) -> 1 | AH21: 5.6982e-09 | AI21: =IF(AH21<Input_values!$B$3,1,0) -> 0 | AJ21: =IF(AND(AI21=1, AG21=1),1,0) -> 0 | AL21: 4.5631e-09 | AM21: =IF(AL21<Input_values!$B$3,1,0) -> 0 | AN21: 1.8072e-08 | AO21: =IF(AN21<Input_values!$B$3,1,0) -> 0 | AP21: =IF(AND(AO21=1, AM21=1),1,0) -> 0
U22: 3 | V22: =AF47 -> 1.3167e-09 | W22: =AF55 -> 1.617e-10 | X22: =AF63 -> 2.0497e-11 | Y22: =AF71 -> 2.629e-12 | Z22: =AF79 -> 7.4182e-13 | AB22: 0.0015 | AC22: 0.002 | AD22: 1.5 | AE22: 16.7 | AF22: 1.1551e-09 | AG22: =IF(AF22<Input_values!$B$3,1,0) -> 0 | AH22: 2.161e-09 | AI22: =IF(AH22<Input_values!$B$3,1,0) -> 0 | AJ22: =IF(AND(AI22=1, AG22=1),1,0) -> 0 | AL22: 6.3946e-09 | AM22: =IF(AL22<Input_values!$B$3,1,0) -> 0 | AN22: 6.8189e-09 | AO22: =IF(AN22<Input_values!$B$3,1,0) -> 0 | AP22: =IF(AND(AO22=1, AM22=1),1,0) -> 0
U23: 4 | V23: =AF48 -> 1.1384e-09 | W23: =AF56 -> 1.4315e-10 | X23: =AF64 -> 1.8355e-11 | Y23: =AF72 -> 2.5344e-12 | Z23: =AF80 -> 8.0528e-13 | AB23: 0.0015 | AC23: 0.003 | AD23: 1.5 | AE23: 16.7 | AF23: 3.4703e-10 | AG23: =IF(AF23<Input_values!$B$3,1,0) -> 1 | AH23: 2.6253e-09 | AI23: =IF(AH23<Input_values!$B$3,1,0) -> 0 | AJ23: =IF(AND(AI23=1, AG23=1),1,0) -> 0 | AL23: 2.6147e-09 | AM23: =IF(AL23<Input_values!$B$3,1,0) -> 0 | AN23: 7.5421e-09 | AO23: =IF(AN23<Input_values!$B$3,1,0) -> 0 | AP23: =IF(AND(AO23=1, AM23=1),1,0) -> 0
U24: 5 | V24: =AF49 -> 1.0577e-09 | W24: =AF57 -> 1.3431e-10 | X24: =AF65 -> 1.7351e-11 | Y24: =AF73 -> 2.5042e-12 | Z24: =AF81 -> 8.7806e-13 | AB24: 0.0015 | AC24: 0.004 | AD24: 1.5 | AE24: 16.7 | AF24: 1.0876e-10 | AG24: =IF(AF24<Input_values!$B$3,1,0) -> 1 | AH24: 2.3135e-09 | AI24: =IF(AH24<Input_values!$B$3,1,0) -> 0 | AJ24: =IF(AND(AI24=1, AG24=1),1,0) -> 0 | AL24: 1.1621e-09 | AM24: =IF(AL24<Input_values!$B$3,1,0) -> 0 | AN24: 7.0835e-09 | AO24: =IF(AN24<Input_values!$B$3,1,0) -> 0 | AP24: =IF(AND(AO24=1, AM24=1),1,0) -> 0
AB25: 0.0015 | AC25: 0.005 | AD25: 1.5 | AE25: 16.7 | AF25: 4.4416e-11 | AG25: =IF(AF25<Input_values!$B$3,1,0) -> 1 | AH25: 2.161e-09 | AI25: =IF(AH25<Input_values!$B$3,1,0) -> 0 | AJ25: =IF(AND(AI25=1, AG25=1),1,0) -> 0 | AL25: 6.1773e-10 | AM25: =IF(AL25<Input_values!$B$3,1,0) -> 1 | AN25: 6.8189e-09 | AO25: =IF(AN25<Input_values!$B$3,1,0) -> 0 | AP25: =IF(AND(AO25=1, AM25=1),1,0) -> 0
U26: y direction / 50 Hz | AB26: 0.002 | AC26: 0.002 | AD26: 1.5 | AE26: 16.7 | AF26: 1.1855e-09 | AG26: =IF(AF26<Input_values!$B$3,1,0) -> 0 | AH26: 2.1805e-09 | AI26: =IF(AH26<Input_values!$B$3,1,0) -> 0 | AJ26: =IF(AND(AI26=1, AG26=1),1,0) -> 0 | AL26: 6.4553e-09 | AM26: =IF(AL26<Input_values!$B$3,1,0) -> 0 | AN26: 6.8697e-09 | AO26: =IF(AN26<Input_values!$B$3,1,0) -> 0 | AP26: =IF(AND(AO26=1, AM26=1),1,0) -> 0
U27: d_alu (m) | V27: 1 | W27: 1.25 | X27: 1.5 | Y27: 1.75 | Z27: 2 | AB27: 0.002 | AC27: 0.003 | AD27: 1.5 | AE27: 16.7 | AF27: 3.6025e-10 | AG27: =IF(AF27<Input_values!$B$3,1,0) -> 1 | AH27: 2.6594e-09 | AI27: =IF(AH27<Input_values!$B$3,1,0) -> 0 | AJ27: =IF(AND(AI27=1, AG27=1),1,0) -> 0 | AL27: 2.6354e-09 | AM27: =IF(AL27<Input_values!$B$3,1,0) -> 0 | AN27: 7.6281e-09 | AO27: =IF(AN27<Input_values!$B$3,1,0) -> 0 | AP27: =IF(AND(AO27=1, AM27=1),1,0) -> 0
U28: 2 | V28: =AH46 -> 1.5338e-08 | W28: =AH54 -> 5.6631e-09 | X28: =AH62 -> 2.0938e-09 | Y28: =AH70 -> 7.8052e-10 | Z28: =AH78 -> 2.9512e-10 | AB28: 0.002 | AC28: 0.004 | AD28: 1.5 | AE28: 16.7 | AF28: 1.153e-10 | AG28: =IF(AF28<Input_values!$B$3,1,0) -> 1 | AH28: 2.3379e-09 | AI28: =IF(AH28<Input_values!$B$3,1,0) -> 0 | AJ28: =IF(AND(AI28=1, AG28=1),1,0) -> 0 | AL28: 1.1696e-09 | AM28: =IF(AL28<Input_values!$B$3,1,0) -> 0 | AN28: 7.1466e-09 | AO28: =IF(AN28<Input_values!$B$3,1,0) -> 0 | AP28: =IF(AND(AO28=1, AM28=1),1,0) -> 0
U29: 3 | V29: =AH47 -> 1.5413e-08 | W29: =AH55 -> 5.7376e-09 | X29: =AH63 -> 2.1421e-09 | Y29: =AH71 -> 8.1065e-10 | Z29: =AH79 -> 3.1385e-10 | AB29: 0.002 | AC29: 0.005 | AD29: 1.5 | AE29: 16.7 | AF29: 4.7039e-11 | AG29: =IF(AF29<Input_values!$B$3,1,0) -> 1 | AH29: 2.1805e-09 | AI29: =IF(AH29<Input_values!$B$3,1,0) -> 0 | AJ29: =IF(AND(AI29=1, AG29=1),1,0) -> 0 | AL29: 6.1992e-10 | AM29: =IF(AL29<Input_values!$B$3,1,0) -> 1 | AN29: 6.8697e-09 | AO29: =IF(AN29<Input_values!$B$3,1,0) -> 0 | AP29: =IF(AND(AO29=1, AM29=1),1,0) -> 0
U30: 4 | V30: =AH48 -> 1.534e-08 | W30: =AH56 -> 5.6773e-09 | X30: =AH64 -> 2.1052e-09 | Y30: =AH72 -> 7.8862e-10 | Z30: =AH80 -> 3.0061e-10 | AB30: 0.0015 | AC30: 0.002 | AD30: 1.75 | AE30: 16.7 | AF30: 2.7363e-10 | AG30: =IF(AF30<Input_values!$B$3,1,0) -> 1 | AH30: 8.3583e-10 | AI30: =IF(AH30<Input_values!$B$3,1,0) -> 1 | AJ30: =IF(AND(AI30=1, AG30=1),1,0) -> 1 | AL30: 1.5985e-09 | AM30: =IF(AL30<Input_values!$B$3,1,0) -> 0 | AN30: 2.6297e-09 | AO30: =IF(AN30<Input_values!$B$3,1,0) -> 0 | AP30: =IF(AND(AO30=1, AM30=1),1,0) -> 0
U31: 5 | V31: =AH49 -> 1.5338e-08 | W31: =AH57 -> 5.6631e-09 | X31: =AH65 -> 2.0938e-09 | Y31: =AH73 -> 7.8052e-10 | Z31: =AH81 -> 2.9512e-10 | AB31: 0.0015 | AC31: 0.003 | AD31: 1.75 | AE31: 16.7 | AF31: 5.93e-11 | AG31: =IF(AF31<Input_values!$B$3,1,0) -> 1 | AH31: 1.0928e-09 | AI31: =IF(AH31<Input_values!$B$3,1,0) -> 0 | AJ31: =IF(AND(AI31=1, AG31=1),1,0) -> 0 | AL31: 5.0778e-10 | AM31: =IF(AL31<Input_values!$B$3,1,0) -> 1 | AN31: 3.138e-09 | AO31: =IF(AN31<Input_values!$B$3,1,0) -> 0 | AP31: =IF(AND(AO31=1, AM31=1),1,0) -> 0
AB32: 0.0015 | AC32: 0.004 | AD32: 1.75 | AE32: 16.7 | AF32: 1.296e-11 | AG32: =IF(AF32<Input_values!$B$3,1,0) -> 1 | AH32: 9.1656e-10 | AI32: =IF(AH32<Input_values!$B$3,1,0) -> 1 | AJ32: =IF(AND(AI32=1, AG32=1),1,0) -> 1 | AL32: 1.7064e-10 | AM32: =IF(AL32<Input_values!$B$3,1,0) -> 1 | AN32: 2.7992e-09 | AO32: =IF(AN32<Input_values!$B$3,1,0) -> 0 | AP32: =IF(AND(AO32=1, AM32=1),1,0) -> 0
AB33: 0.0015 | AC33: 0.005 | AD33: 1.75 | AE33: 16.7 | AF33: 4.934e-12 | AG33: =IF(AF33<Input_values!$B$3,1,0) -> 1 | AH33: 8.3583e-10 | AI33: =IF(AH33<Input_values!$B$3,1,0) -> 1 | AJ33: =IF(AND(AI33=1, AG33=1),1,0) -> 1 | AL33: 7.3073e-11 | AM33: =IF(AL33<Input_values!$B$3,1,0) -> 1 | AN33: 2.6297e-09 | AO33: =IF(AN33<Input_values!$B$3,1,0) -> 0 | AP33: =IF(AND(AO33=1, AM33=1),1,0) -> 0
AB34: 0.002 | AC34: 0.002 | AD34: 1.75 | AE34: 16.7 | AF34: 3.0236e-10 | AG34: =IF(AF34<Input_values!$B$3,1,0) -> 1 | AH34: 8.4474e-10 | AI34: =IF(AH34<Input_values!$B$3,1,0) -> 1 | AJ34: =IF(AND(AI34=1, AG34=1),1,0) -> 1 | AL34: 1.6328e-09 | AM34: =IF(AL34<Input_values!$B$3,1,0) -> 0 | AN34: 2.6524e-09 | AO34: =IF(AN34<Input_values!$B$3,1,0) -> 0 | AP34: =IF(AND(AO34=1, AM34=1),1,0) -> 0
AB35: 0.002 | AC35: 0.003 | AD35: 1.75 | AE35: 16.7 | AF35: 7.1774e-11 | AG35: =IF(AF35<Input_values!$B$3,1,0) -> 1 | AH35: 1.1079e-09 | AI35: =IF(AH35<Input_values!$B$3,1,0) -> 0 | AJ35: =IF(AND(AI35=1, AG35=1),1,0) -> 0 | AL35: 5.223e-10 | AM35: =IF(AL35<Input_values!$B$3,1,0) -> 1 | AN35: 3.1778e-09 | AO35: =IF(AN35<Input_values!$B$3,1,0) -> 0 | AP35: =IF(AND(AO35=1, AM35=1),1,0) -> 0
AB36: 0.002 | AC36: 0.004 | AD36: 1.75 | AE36: 16.7 | AF36: 1.7379e-11 | AG36: =IF(AF36<Input_values!$B$3,1,0) -> 1 | AH36: 9.276e-10 | AI36: =IF(AH36<Input_values!$B$3,1,0) -> 1 | AJ36: =IF(AND(AI36=1, AG36=1),1,0) -> 1 | AL36: 1.775e-10 | AM36: =IF(AL36<Input_values!$B$3,1,0) -> 1 | AN36: 2.8276e-09 | AO36: =IF(AN36<Input_values!$B$3,1,0) -> 0 | AP36: =IF(AND(AO36=1, AM36=1),1,0) -> 0
AB37: 0.002 | AC37: 0.005 | AD37: 1.75 | AE37: 16.7 | AF37: 5.8745e-12 | AG37: =IF(AF37<Input_values!$B$3,1,0) -> 1 | AH37: 8.4474e-10 | AI37: =IF(AH37<Input_values!$B$3,1,0) -> 1 | AJ37: =IF(AND(AI37=1, AG37=1),1,0) -> 1 | AL37: 7.5639e-11 | AM37: =IF(AL37<Input_values!$B$3,1,0) -> 1 | AN37: 2.6524e-09 | AO37: =IF(AN37<Input_values!$B$3,1,0) -> 0 | AP37: =IF(AND(AO37=1, AM37=1),1,0) -> 0
AB38: 0.0015 | AC38: 0.002 | AD38: 2 | AE38: 16.7 | AF38: 5.2092e-11 | AG38: =IF(AF38<Input_values!$B$3,1,0) -> 1 | AH38: 3.3045e-10 | AI38: =IF(AH38<Input_values!$B$3,1,0) -> 1 | AJ38: =IF(AND(AI38=1, AG38=1),1,0) -> 1 | AL38: 3.8383e-10 | AM38: =IF(AL38<Input_values!$B$3,1,0) -> 1 | AN38: 1.013e-09 | AO38: =IF(AN38<Input_values!$B$3,1,0) -> 0 | AP38: =IF(AND(AO38=1, AM38=1),1,0) -> 0
AB39: 0.0015 | AC39: 0.003 | AD39: 2 | AE39: 16.7 | AF39: 1.7335e-11 | AG39: =IF(AF39<Input_values!$B$3,1,0) -> 1 | AH39: 4.6423e-10 | AI39: =IF(AH39<Input_values!$B$3,1,0) -> 1 | AJ39: =IF(AND(AI39=1, AG39=1),1,0) -> 1 | AL39: 8.9716e-11 | AM39: =IF(AL39<Input_values!$B$3,1,0) -> 1 | AN39: 1.3016e-09 | AO39: =IF(AN39<Input_values!$B$3,1,0) -> 0 | AP39: =IF(AND(AO39=1, AM39=1),1,0) -> 0
AB40: 0.0015 | AC40: 0.004 | AD40: 2 | AE40: 16.7 | AF40: 8.7617e-12 | AG40: =IF(AF40<Input_values!$B$3,1,0) -> 1 | AH40: 3.7169e-10 | AI40: =IF(AH40<Input_values!$B$3,1,0) -> 1 | AJ40: =IF(AND(AI40=1, AG40=1),1,0) -> 1 | AL40: 2.0914e-11 | AM40: =IF(AL40<Input_values!$B$3,1,0) -> 1 | AN40: 1.1043e-09 | AO40: =IF(AN40<Input_values!$B$3,1,0) -> 0 | AP40: =IF(AND(AO40=1, AM40=1),1,0) -> 0
AB41: 0.0015 | AC41: 0.005 | AD41: 2 | AE41: 16.7 | AF41: 5.4894e-12 | AG41: =IF(AF41<Input_values!$B$3,1,0) -> 1 | AH41: 3.3045e-10 | AI41: =IF(AH41<Input_values!$B$3,1,0) -> 1 | AJ41: =IF(AND(AI41=1, AG41=1),1,0) -> 1 | AL41: 7.9423e-12 | AM41: =IF(AL41<Input_values!$B$3,1,0) -> 1 | AN41: 1.013e-09 | AO41: =IF(AN41<Input_values!$B$3,1,0) -> 0 | AP41: =IF(AND(AO41=1, AM41=1),1,0) -> 0
...
